Workbook

Sheet Historicals
A1: Logitech – historical financials (USD thousands, years ended 31 March)
A2: Blue = typed in from Logitech's SEC results releases. Black = formula.
A4: USD thousands | B4: FY2022 | C4: FY2023 | D4: FY2024 | E4: FY2025 | F4: FY2026
A6: INCOME STATEMENT
A7: Net sales | B7: 5481101 | C7: 4538818 | D7: 4298467 | E7: 4554900 | F7: 4840761
A8: Cost of goods sold | B8: 3204072 | C8: 2806438 | D8: 2509418 | E8: 2582745 | F8: 2742407
A9: Amortization of intangibles (in cost of sales) | B9: 14023 | C9: 12865 | D9: 11028 | E9: 9554 | F9: 7017
A10: Gross profit (as reported) | B10: 2263006 | C10: 1719515 | D10: 1778021 | E10: 1962601 | F10: 2091337
A11: Marketing and selling | B11: 1025899 | C11: 809182 | D11: 730310 | E11: 814414 | F11: 816604
A12: Research and development | B12: 291844 | C12: 280796 | D12: 287243 | E12: 309008 | F12: 316221
A13: General and administrative | B13: 148648 | C13: 124652 | D13: 155056 | E13: 164014 | F13: 167160
A14: Amortization of intangibles & acquisition-related costs | B14: 16947 | C14: 11843 | D14: 10934 | E14: 10695 | F14: 6298
A15: Impairment of intangible assets | B15: 7000 | C15: 0 | D15: 3526 | E15: 0 | F15: 0
A16: Change in fair value of contingent consideration | B16: -3509 | C16: 0 | D16: -250 | E16: 0 | F16: 0
A17: Restructuring charges, net | B17: 2165 | C17: 34573 | D17: 3866 | E17: 9615 | F17: 9860
A18: Total operating expenses (as reported) | B18: 1488994 | C18: 1261046 | D18: 1190685 | E18: 1307746 | F18: 1316143
... A26: Diluted weighted average shares (thousands) | B26: 170414 | C26: 163704 | D26: 158171 | E26: 152784 | F26: 148208
A28: BALANCE SHEET (31 March)
A29: Cash and cash equivalents | B29: 1328716 | C29: 1149023 | D29: 1520842 | E29: 1503205 | F29: 1741546
A30: Accounts receivable, net | B30: 675604 | C30: 630382 | D30: 541715 | E30: 454546 | F30: 505867
A31: Inventories | B31: 933124 | C31: 682893 | D31: 422513 | E31: 503747 | F31: 489948
A32: Other current assets | B32: 135478 | C32: 142876 | D32: 146270 | E32: 131211 | F32: 177895
A33: Total current assets (as reported) | B33: 3072922 | C33: 2605174 | D33: 2631340 | E33: 2592709 | F33: 2915256
A34: Property, plant and equipment, net | B34: 109807 | C34: 121503 | D34: 116589 | E34: 113858 | F34: 116454
A35: Goodwill | B35: 448175 | C35: 454610 | D35: 461978 | E35: 463230 | F35: 465417
A36: Other intangible assets, net | B36: 83779 | C36: 63173 | D36: 44603 | E36: 24630 | F36: 12386
A37: Other assets | B37: 320722 | C37: 316293 | D37: 350194 | E37: 344077 | F37: 339075
A38: Total assets (as reported) | B38: 4035405 | C38: 3560753 | D38: 3604704 | E38: 3538504 | F38: 3848588
A39: Accounts payable | B39: 636306 | C39: 406968 | D39: 448627 | E39: 414586 | F39: 530983
A40: Accrued and other current liabilities | B40: 784848 | C40: 643139 | D40: 637262 | E40: 686503 | F40: 781990
... A48: Treasury shares (thousands) | B48: 7855 | C48: 13763 | D48: 19243 | E48: 20485 | F48: 17282
A50: CASH FLOW STATEMENT
A51: Net income | B51: 644513 | C51: 364575 | D51: 612143 | E51: 631529 | F51: 711187
A52: Depreciation | B52: 88361 | C52: 76309 | D52: 63065 | E52: 59664 | F52: 64139
A53: Amortization of intangible assets | B53: 30179 | C53: 24407 | D53: 21681 | E53: 20098 | F53: 13315
A54: Share-based compensation expense | B54: 93479 | C54: 70782 | D54: 82889 | E54: 89913 | F54: 112392
A55: Net cash provided by operating activities | B55: 298318 | C55: 534010 | D55: 1145116 | E55: 842557 | F55: 1037207
A56: Purchases of property, plant and equipment | B56: 89152 | C56: 92353 | D56: 55897 | E56: 56128 | F56: 61562
A57: Share repurchases | B57: 412022 | C57: 418346 | D57: 504203 | E57: 588838 | F57: 534939
A58: Dividends paid | B58: 159410 | C58: 158680 | D58: 182305 | E58: 207853 | F58: 233059
...

Sheet Assumptions
A1: Assumptions (blue cells are the ones you can change)
A3: MARKET DATA
A4: Share price (USD), 16 Oct 2026 | B4: 104.41
A5: Shares outstanding (millions) | B5: =(Historicals!F47-Historicals!F48)/1000 -> 143.502
A6: Cash (USD m), 31 Mar 2026 | B6: =Historicals!F29/1000 -> 1741.546
A7: Debt (USD m) | B7: 0 | C7: Logitech has no borrowings on its balance sheet
A9: REQUIRED RETURN (CAPM)
A10: Risk-free rate (US 10-yr Treasury yield) | B10: 0.051
A11: Beta (adjusted) | B11: =0.67*0.59+0.33 -> 0.7253 | C11: Raw beta 0.59, pulled towards 1 (Blume)
A12: Equity risk premium | B12: 0.045
A13: Cost of equity = risk-free + beta × premium | B13: =B10+B11*B12 -> 0.0836385
A14: WACC (discount rate) | B14: =B13 -> 0.0836385 | C14: No debt, so WACC = cost of equity
A16: TERMINAL VALUE
A17: Perpetuity growth rate | B17: 0.025
A18: Exit EV/EBITDA multiple | B18: 14
A20: FORECAST DRIVERS
B21: FY2027E | C21: FY2028E | D21: FY2029E | E21: FY2030E | F21: FY2031E
A22: Gaming – sales growth | B22: 0.05 | C22: 0.05 | D22: 0.04 | E22: 0.04 | F22: 0.03
A23: Keyboards & Combos – sales growth | B23: 0.04 | C23: 0.04 | D23: 0.035 | E23: 0.03 | F23: 0.03
A24: Pointing Devices – sales growth | B24: 0.06 | C24: 0.05 | D24: 0.04 | E24: 0.04 | F24: 0.03
A25: Video Collaboration – sales growth | B25: 0.07 | C25: 0.06 | D25: 0.05 | E25: 0.04 | F25: 0.03
A26: Webcams – sales growth | B26: 0.03 | C26: 0.03 | D26: 0.03 | E26: 0.025 | F26: 0.025
A27: Tablet Accessories – sales growth | B27: 0.08 | C27: 0.06 | D27: 0.05 | E27: 0.04 | F27: 0.03
A28: Headsets – sales growth | B28: 0.02 | C28: 0.02 | D28: 0.02 | E28: 0.02 | F28: 0.02
A29: Other – sales growth | B29: -0.1 | C29: -0.05 | D29: 0 | E29: 0 | F29: 0
A30: Gross margin | B30: 0.432 | C30: 0.433 | D30: 0.434 | E30: 0.434 | F30: 0.434
A31: Marketing & selling, % of sales | B31: 0.168 | C31: 0.167 | D31: 0.166 | E31: 0.165 | F31: 0.165
A32: R&D, % of sales | B32: 0.065 | C32: 0.065 | D32: 0.065 | E32: 0.065 | F32: 0.065
A33: G&A, % of sales | B33: 0.034 | C33: 0.034 | D33: 0.034 | E33: 0.034 | F33: 0.034
... A37: Cash tied up in working capital, % of extra sales | B37: 0.05 | C37: 0.05 | D37: 0.05 | E37: 0.05 | F37: 0.05
A39: Basis: category growth tapers towards 3%; gross margin held near FY2026's 43.2%; costs near FY2026 ratios; tax slightly above FY2026's 14%; capex ≈ depreciation.

Sheet DCF
A1: Logitech – DCF valuation (USD millions)
A2: Valuation as at 31 March 2026 (FY2026 year-end balance sheet). Cash flows are discounted as arriving at the end of each year.
A4: USD m | B4: FY2022A | C4: FY2023A | D4: FY2024A | E4: FY2025A | F4: FY2026A | G4: FY2027E | H4: FY2028E | I4: FY2029E | J4: FY2030E | K4: FY2031E
A5: NET SALES BY PRODUCT
A6: Gaming | C6: =Historicals!C61/1000 -> 1288.313 | D6: =Historicals!D61/1000 -> 1231.063 | E6: =Historicals!E61/1000 -> 1338.467 | F6: =Historicals!F61/1000 -> 1414.206 | G6: =F6*(1+Assumptions!B22) -> 1484.9163 | H6: =G6*(1+Assumptions!C22) -> 1559.1621 | I6: =H6*(1+Assumptions!D22) -> 1621.5286 | J6: =I6*(1+Assumptions!E22) -> 1686.3897 | K6: =J6*(1+Assumptions!F22) -> 1736.9814
A7: Keyboards & Combos | C7: =Historicals!C62/1000 -> 836.432 | D7: =Historicals!D62/1000 -> 821.441 | E7: =Historicals!E62/1000 -> 882.643 | F7: =Historicals!F62/1000 -> 937.551 | G7: =F7*(1+Assumptions!B23) -> 975.05304 | H7: =G7*(1+Assumptions!C23) -> 1014.0552 | I7: =H7*(1+Assumptions!D23) -> 1049.5471 | J7: =I7*(1+Assumptions!E23) -> 1081.0335 | K7: =J7*(1+Assumptions!F23) -> 1113.4645
A8: Pointing Devices | C8: =Historicals!C63/1000 -> 728.357 | D8: =Historicals!D63/1000 -> 742.987 | E8: =Historicals!E63/1000 -> 788.784 | F8: =Historicals!F63/1000 -> 858.904 | G8: =F8*(1+Assumptions!B24) -> 910.43824 | H8: =G8*(1+Assumptions!C24) -> 955.96015 | I8: =H8*(1+Assumptions!D24) -> 994.19856 | J8: =I8*(1+Assumptions!E24) -> 1033.9665 | K8: =J8*(1+Assumptions!F24) -> 1064.9855
A9: Video Collaboration | C9: =Historicals!C64/1000 -> 677.923 | D9: =Historicals!D64/1000 -> 609.361 | E9: =Historicals!E64/1000 -> 626 | F9: =Historicals!F64/1000 -> 689.04 | G9: =F9*(1+Assumptions!B25) -> 737.2728 | H9: =G9*(1+Assumptions!C25) -> 781.50917 | I9: =H9*(1+Assumptions!D25) -> 820.58463 | J9: =I9*(1+Assumptions!E25) -> 853.40801 | K9: =J9*(1+Assumptions!F25) -> 879.01025
A10: Webcams | C10: =Historicals!C65/1000 -> 378.688 | D10: =Historicals!D65/1000 -> 325.225 | E10: =Historicals!E65/1000 -> 315.52 | F10: =Historicals!F65/1000 -> 326.172 | G10: =F10*(1+Assumptions!B26) -> 335.95716 | H10: =G10*(1+Assumptions!C26) -> 346.03587 | I10: =H10*(1+Assumptions!D26) -> 356.41695 | J10: =I10*(1+Assumptions!E26) -> 365.32737 | K10: =J10*(1+Assumptions!F26) -> 374.46056
A11: Tablet Accessories | C11: =Historicals!C66/1000 -> 254.374 | D11: =Historicals!D66/1000 -> 254.06 | E11: =Historicals!E66/1000 -> 299.54 | F11: =Historicals!F66/1000 -> 336.189 | G11: =F11*(1+Assumptions!B27) -> 363.08412 | H11: =G11*(1+Assumptions!C27) -> 384.86917 | I11: =H11*(1+Assumptions!D27) -> 404.11263 | J11: =I11*(1+Assumptions!E27) -> 420.27713 | K11: =J11*(1+Assumptions!F27) -> 432.88544
A12: Headsets | C12: =Historicals!C67/1000 -> 176.576 | D12: =Historicals!D67/1000 -> 168.478 | E12: =Historicals!E67/1000 -> 179.71 | F12: =Historicals!F67/1000 -> 179.825 | G12: =F12*(1+Assumptions!B28) -> 183.4215 | H12: =G12*(1+Assumptions!C28) -> 187.08993 | I12: =H12*(1+Assumptions!D28) -> 190.83173 | J12: =I12*(1+Assumptions!E28) -> 194.64836 | K12: =J12*(1+Assumptions!F28) -> 198.54133
A13: Other | C13: =Historicals!C68/1000 -> 198.155 | D13: =Historicals!D68/1000 -> 145.852 | E13: =Historicals!E68/1000 -> 124.236 | F13: =Historicals!F68/1000 -> 98.874 | G13: =F13*(1+Assumptions!B29) -> 88.9866 | H13: =G13*(1+Assumptions!C29) -> 84.53727 | I13: =H13*(1+Assumptions!D29) -> 84.53727 | J13: =I13*(1+Assumptions!E29) -> 84.53727 | K13: =J13*(1+Assumptions!F29) -> 84.53727
A14: Total net sales | B14: =Historicals!B7/1000 -> 5481.101 | C14: =Historicals!C7/1000 -> 4538.818 | D14: =Historicals!D7/1000 -> 4298.467 | E14: =Historicals!E7/1000 -> 4554.9 | F14: =Historicals!F7/1000 -> 4840.761 | G14: =SUM(G6:G13) -> 5079.1298 | H14: =SUM(H6:H13) -> 5313.2188 | I14: =SUM(I6:I13) -> 5521.7575 | J14: =SUM(J6:J13) -> 5719.5879 | K14: =SUM(K6:K13) -> 5884.8663
A15: growth | C15: =C14/B14-1 -> -0.17191491 | D15: =D14/C14-1 -> -0.052954536 | E15: =E14/D14-1 -> 0.05965685 | F15: =F14/E14-1 -> 0.062759007 | G15: =G14/F14-1 -> 0.049242001 | H15: =H14/G14-1 -> 0.046088423 | I15: =I14/H14-1 -> 0.039249016 | J15: =J14/I14-1 -> 0.035827442 | K15: =K14/J14-1 -> 0.028896907
A17: Gross profit | B17: =Historicals!B10/1000 -> 2263.006 | C17: =Historicals!C10/1000 -> 1719.515 | D17: =Historicals!D10/1000 -> 1778.021 | E17: =Historicals!E10/1000 -> 1962.601 | F17: =Historicals!F10/1000 -> 2091.337 | G17: =G14*Assumptions!B30 -> 2194.1841 | H17: =H14*Assumptions!C30 -> 2300.6238 | I17: =I14*Assumptions!D30 -> 2396.4427 | J17: =J14*Assumptions!E30 -> 2482.3011 | K17: =K14*Assumptions!F30 -> 2554.032
A18: gross margin | B18: =B17/B14 -> 0.41287435 | C18: =C17/C14 -> 0.37884643 | D18: =D17/D14 -> 0.41364072 | E18: =E17/E14 -> 0.43087686 | F18: =F17/F14 -> 0.43202649 | G18: =G17/G14 -> 0.432 | H18: =H17/H14 -> 0.433 | I18: =I17/I14 -> 0.434 | ... K18: =K17/K14 -> 0.434
A19: Marketing & selling | B19: =-Historicals!B11/1000 -> -1025.899 | C19: =-Historicals!C11/1000 -> -809.182 | D19: =-Historicals!D11/1000 -> -730.31 | E19: =-Historicals!E11/1000 -> -814.414 | F19: =-Historicals!F11/1000 -> -816.604 | G19: =-G14*Assumptions!B31 -> -853.2938 | H19: =-H14*Assumptions!C31 -> -887.30755 | I19: =-I14*Assumptions!D31 -> -916.61174 | J19: =-J14*Assumptions!E31 -> -943.732 | K19: =-K14*Assumptions!F31 -> -971.00294
A20: Research & development | B20: =-Historicals!B12/1000 -> -291.844 | C20: =-Historicals!C12/1000 -> -280.796 | D20: =-Historicals!D12/1000 -> -287.243 | E20: =-Historicals!E12/1000 -> -309.008 | F20: =-Historicals!F12/1000 -> -316.221 | G20: =-G14*Assumptions!B32 -> -330.14343 | H20: =-H14*Assumptions!C32 -> -345.35922 | I20: =-I14*Assumptions!D32 -> -358.91423 | J20: =-J14*Assumptions!E32 -> -371.77321 | K20: =-K14*Assumptions!F32 -> -382.51631
A21: General & administrative | B21: =-Historicals!B13/1000 -> -148.648 | C21: =-Historicals!C13/1000 -> -124.652 | D21: =-Historicals!D13/1000 -> -155.056 | E21: =-Historicals!E13/1000 -> -164.014 | F21: =-Historicals!F13/1000 -> -167.16 | G21: =-G14*Assumptions!B33 -> -172.69041 | H21: =-H14*Assumptions!C33 -> -180.64944 | I21: =-I14*Assumptions!D33 -> -187.73975 | J21: =-J14*Assumptions!E33 -> -194.46599 | K21: =-K14*Assumptions!F33 -> -200.08545
A22: Operating profit (EBIT) | B22: =Historicals!B19/1000 -> 774.012 | C22: =Historicals!C19/1000 -> 458.469 | D22: =Historicals!D19/1000 -> 587.336 | E22: =Historicals!E19/1000 -> 654.855 | F22: =Historicals!F19/1000 -> 775.194 | G22: =SUM(G17,G19:G21) -> 838.05641 | H22: =SUM(H17,H19:H21) -> 887.30755 | I22: =SUM(I17,I19:I21) -> 933.17701 | J22: =SUM(J17,J19:J21) -> 972.32994 | K22: =SUM(K17,K19:K21) -> 1000.4273
A23: EBIT margin | B23: =B22/B14 -> 0.14121469 | C23: =C22/C14 -> 0.10101066 | D23: =D22/D14 -> 0.13663848 | E23: =E22/E14 -> 0.14376935 | F23: =F22/F14 -> 0.16013887 | G23: =G22/G14 -> 0.165 | H23: =H22/H14 -> 0.167 | I23: =I22/I14 -> 0.169 | ... K23: =K22/K14 -> 0.17
A24: (historical EBIT is as reported, so it also includes small amortization, restructuring and impairment items)
A26: FREE CASH FLOW
A27: EBIT | G27: =G22 -> 838.05641 | H27: =H22 -> 887.30755 | I27: =I22 -> 933.17701 | J27: =J22 -> 972.32994 | K27: =K22 -> 1000.4273
A28: Less: tax on EBIT | G28: =-G27*Assumptions!B34 -> -125.70846 | H28: =-H27*Assumptions!C34 -> -133.09613 | I28: =-I27*Assumptions!D34 -> -139.97655 | J28: =-J27*Assumptions!E34 -> -145.84949 | K28: =-K27*Assumptions!F34 -> -150.06409
A29: Plus: depreciation | G29: =G14*Assumptions!B35 -> 66.028687 | H29: =H14*Assumptions!C35 -> 69.071845 | I29: =I14*Assumptions!D35 -> 71.782847 | J29: =J14*Assumptions!E35 -> 74.354643 | K29: =K14*Assumptions!F35 -> 76.503262
A30: Less: capital expenditure | G30: =-G14*Assumptions!B36 -> -66.028687 | H30: =-H14*Assumptions!C36 -> -69.071845 | I30: =-I14*Assumptions!D36 -> -71.782847 | J30: =-J14*Assumptions!E36 -> -74.354643 | K30: =-K14*Assumptions!F36 -> -76.503262
A31: Less: cash tied up in working capital | G31: =-(G14-F14)*Assumptions!B37 -> -11.918438 | H31: =-(H14-G14)*Assumptions!C37 -> -11.704454 | I31: =-(I14-H14)*Assumptions!D37 -> -10.426931 | J31: =-(J14-I14)*Assumptions!E37 -> -9.8915224 | K31: =-(K14-J14)*Assumptions!F37 -> -8.2639199
A32: Free cash flow (FCF) | G32: =SUM(G27:G31) -> 700.42951 | H32: =SUM(H27:H31) -> 742.50696 | I32: =SUM(I27:I31) -> 782.77353 | J32: =SUM(J27:J31) -> 816.58893 | K32: =SUM(K27:K31) -> 842.09926
A33: Memo: Logitech's reported free cash flow (operating cash flow − capex) | B33: =(Historicals!B55-Historicals!B56)/1000 -> 209.166 | C33: =(Historicals!C55-Historicals!C56)/1000 -> 441.657 | D33: =(Historicals!D55-Historicals!D56)/1000 -> 1089.219 | E33: =(Historicals!E55-Historicals!E56)/1000 -> 786.429 | F33: =(Historicals!F55-Historicals!F56)/1000 -> 975.645
A35: Year number | G35: 1 | H35: 2 | I35: 3 | J35: 4 | K35: 5
A36: Discount factor = 1 / (1 + WACC)^year | G36: =1/(1+Assumptions!$B$14)^G35 -> 0.92281697 | H36: =1/(1+Assumptions!$B$14)^H35 -> 0.85159116 | I36: =1/(1+Assumptions!$B$14)^I35 -> 0.78586278 | J36: =1/(1+Assumptions!$B$14)^J35 -> 0.72520751 | K36: =1/(1+Assumptions!$B$14)^K35 -> 0.6692338
A37: Present value of FCF | G37: =G32*G36 -> 646.36824 | H37: =H32*H36 -> 632.31237 | I37: =I32*I36 -> 615.15258 | J37: =J32*J36 -> 592.19643 | K37: =K32*K36 -> 563.56129
A39: VALUATION – PERPETUITY GROWTH METHOD
A40: Sum of present value of FCF (FY2027–FY2031) | B40: =SUM(G37:K37) -> 3049.5909
A41: Terminal value at end of FY2031 = FCF × (1+g) ÷ (WACC − g) | B41: =K32*(1+Assumptions!B17)/(Assumptions!B14-Assumptions!B17) -> 14719.881
A42: Present value of terminal value | B42: =B41*K36 -> 9851.0419
A43: Enterprise value | B43: =B40+B42 -> 12900.633
A44: Plus: cash | B44: =Assumptions!B6 -> 1741.546
A45: Less: debt | B45: =-Assumptions!B7 -> 0
...

Sheet Sensitivity
A1: Sensitivity – value per share (USD)
A2: Each cell recalculates the whole valuation with a different WACC and growth rate (or exit multiple). Centre cell = base case.
A4: Perpetuity growth method: WACC (down) vs growth rate (across)
A5: WACC / growth | B5: =Assumptions!$B$17+(-0.01) -> 0.015 | C5: =Assumptions!$B$17+(-0.005) -> 0.02 | D5: =Assumptions!$B$17+(0) -> 0.025 | E5: =Assumptions!$B$17+(0.005) -> 0.03 | F5: =Assumptions!$B$17+(0.01) -> 0.035
A6: =Assumptions!$B$14+(-0.01) -> 0.0736385 | B6: =(NPV($A6,DCF!$G$32:$K$32)+DCF!$K$32*(1+B$5)/($A6-B$5)/(1+$A6)^5+Assumptions!$B$6-Assumptions!$B$7)/Assumptions!$B$5 -> 105.17778 | C6: =(NPV($A6,DCF!$G$32:$K$32)+DCF!$K$32*(1+C$5)/($A6-C$5)/(1+$A6)^5+Assumptions!$B$6-Assumptions!$B$7)/Assumptions!$B$5 -> 112.19853 | D6: =(NPV($A6,DCF!$G$32:$K$32)+DCF!$K$32*(1+D$5)/($A6-D$5)/(1+$A6)^5+Assumptions!$B$6-Assumptions!$B$7)/Assumptions!$B$5 -> 120.66274 | E6: =(NPV($A6,DCF!$G$32:$K$32)+DCF!$K$32*(1+E$5)/($A6-E$5)/(1+$A6)^5+Assumptions!$B$6-Assumptions!$B$7)/Assumptions!$B$5 -> 131.06656 | F6: =(NPV($A6,DCF!$G$32:$K$32)+DCF!$K$32*(1+F$5)/($A6-F$5)/(1+$A6)^5+Assumptions!$B$6-Assumptions!$B$7)/Assumptions!$B$5 -> 144.16299
A7: =Assumptions!$B$14+(-0.005) -> 0.0786385 | B7: =(NPV($A7,DCF!$G$32:$K$32)+DCF!$K$32*(1+B$5)/($A7-B$5)/(1+$A7)^5+Assumptions!$B$6-Assumptions!$B$7)/Assumptions!$B$5 -> 97.779924 | C7: =(NPV($A7,DCF!$G$32:$K$32)+DCF!$K$32*(1+C$5)/($A7-C$5)/(1+$A7)^5+Assumptions!$B$6-Assumptions!$B$7)/Assumptions!$B$5 -> 103.58849 | D7: =(NPV($A7,DCF!$G$32:$K$32)+DCF!$K$32*(1+D$5)/($A7-D$5)/(1+$A7)^5+Assumptions!$B$6-Assumptions!$B$7)/Assumptions!$B$5 -> 110.47996 | E7: =(NPV($A7,DCF!$G$32:$K$32)+DCF!$K$32*(1+E$5)/($A7-E$5)/(1+$A7)^5+Assumptions!$B$6-Assumptions!$B$7)/Assumptions!$B$5 -> 118.78832 | F7: =(NPV($A7,DCF!$G$32:$K$32)+DCF!$K$32*(1+F$5)/($A7-F$5)/(1+$A7)^5+Assumptions!$B$6-Assumptions!$B$7)/Assumptions!$B$5 -> 129.00057
A8: =Assumptions!$B$14+(0) -> 0.0836385 | B8: =(NPV($A8,DCF!$G$32:$K$32)+DCF!$K$32*(1+B$5)/($A8-B$5)/(1+$A8)^5+Assumptions!$B$6-Assumptions!$B$7)/Assumptions!$B$5 -> 91.461211 | C8: =(NPV($A8,DCF!$G$32:$K$32)+DCF!$K$32*(1+C$5)/($A8-C$5)/(1+$A8)^5+Assumptions!$B$6-Assumptions!$B$7)/Assumptions!$B$5 -> 96.332567 | D8: =(NPV($A8,DCF!$G$32:$K$32)+DCF!$K$32*(1+D$5)/($A8-D$5)/(1+$A8)^5+Assumptions!$B$6-Assumptions!$B$7)/Assumptions!$B$5 -> 102.03467 | E8: =(NPV($A8,DCF!$G$32:$K$32)+DCF!$K$32*(1+E$5)/($A8-E$5)/(1+$A8)^5+Assumptions!$B$6-Assumptions!$B$7)/Assumptions!$B$5 -> 108.79983 | F8: =(NPV($A8,DCF!$G$32:$K$32)+DCF!$K$32*(1+F$5)/($A8-F$5)/(1+$A8)^5+Assumptions!$B$6-Assumptions!$B$7)/Assumptions!$B$5 -> 116.9559
A9: =Assumptions!$B$14+(0.005) -> 0.0886385 | B9: =(NPV($A9,DCF!$G$32:$K$32)+DCF!$K$32*(1+B$5)/($A9-B$5)/(1+$A9)^5+Assumptions!$B$6-Assumptions!$B$7)/Assumptions!$B$5 -> 86.001793 | C9: =(NPV($A9,DCF!$G$32:$K$32)+DCF!$K$32*(1+C$5)/($A9-C$5)/(1+$A9)^5+Assumptions!$B$6-Assumptions!$B$7)/Assumptions!$B$5 -> 90.134817 | D9: =(NPV($A9,DCF!$G$32:$K$32)+DCF!$K$32*(1+D$5)/($A9-D$5)/(1+$A9)^5+Assumptions!$B$6-Assumptions!$B$7)/Assumptions!$B$5 -> 94.917293 | E9: =(NPV($A9,DCF!$G$32:$K$32)+DCF!$K$32*(1+E$5)/($A9-E$5)/(1+$A9)^5+Assumptions!$B$6-Assumptions!$B$7)/Assumptions!$B$5 -> 100.51536 | F9: =(NPV($A9,DCF!$G$32:$K$32)+DCF!$K$32*(1+F$5)/($A9-F$5)/(1+$A9)^5+Assumptions!$B$6-Assumptions!$B$7)/Assumptions!$B$5 -> 107.15708
A10: =Assumptions!$B$14+(0.01) -> 0.0936385 | B10: =(NPV($A10,DCF!$G$32:$K$32)+DCF!$K$32*(1+B$5)/($A10-B$5)/(1+$A10)^5+Assumptions!$B$6-Assumptions!$B$7)/Assumptions!$B$5 -> 81.237739 | C10: =(NPV($A10,DCF!$G$32:$K$32)+DCF!$K$32*(1+C$5)/($A10-C$5)/(1+$A10)^5+Assumptions!$B$6-Assumptions!$B$7)/Assumptions!$B$5 -> 84.77967 | D10: =(NPV($A10,DCF!$G$32:$K$32)+DCF!$K$32*(1+D$5)/($A10-D$5)/(1+$A10)^5+Assumptions!$B$6-Assumptions!$B$7)/Assumptions!$B$5 -> 88.837627 | E10: =(NPV($A10,DCF!$G$32:$K$32)+DCF!$K$32*(1+E$5)/($A10-E$5)/(1+$A10)^5+Assumptions!$B$6-Assumptions!$B$7)/Assumptions!$B$5 -> 93.533241 | F10: =(NPV($A10,DCF!$G$32:$K$32)+DCF!$K$32*(1+F$5)/($A10-F$5)/(1+$A10)^5+Assumptions!$B$6-Assumptions!$B$7)/Assumptions!$B$5 -> 99.02963
A13: Exit multiple method: WACC (down) vs EV/EBITDA multiple (across)
A14: WACC / multiple | B14: =Assumptions!$B$18+(-2) -> 12 | C14: =Assumptions!$B$18+(-1) -> 13 | D14: =Assumptions!$B$18+(0) -> 14 | E14: =Assumptions!$B$18+(1) -> 15 | F14: =Assumptions!$B$18+(2) -> 16
A15: =Assumptions!$B$14+(-0.01) -> 0.0736385 | B15: =(NPV($A15,DCF!$G$32:$K$32)+(DCF!$K$22+DCF!$K$29)*B$14/(1+$A15)^5+Assumptions!$B$6-Assumptions!$B$7)/Assumptions!$B$5 -> 97.102598 | C15: =(NPV($A15,DCF!$G$32:$K$32)+(DCF!$K$22+DCF!$K$29)*C$14/(1+$A15)^5+Assumptions!$B$6-Assumptions!$B$7)/Assumptions!$B$5 -> 102.36325 | D15: =(NPV($A15,DCF!$G$32:$K$32)+(DCF!$K$22+DCF!$K$29)*D$14/(1+$A15)^5+Assumptions!$B$6-Assumptions!$B$7)/Assumptions!$B$5 -> 107.6239 | E15: =(NPV($A15,DCF!$G$32:$K$32)+(DCF!$K$22+DCF!$K$29)*E$14/(1+$A15)^5+Assumptions!$B$6-Assumptions!$B$7)/Assumptions!$B$5 -> 112.88455 | F15: =(NPV($A15,DCF!$G$32:$K$32)+(DCF!$K$22+DCF!$K$29)*F$14/(1+$A15)^5+Assumptions!$B$6-Assumptions!$B$7)/Assumptions!$B$5 -> 118.1452
A16: =Assumptions!$B$14+(-0.005) -> 0.0786385 | B16: =(NPV($A16,DCF!$G$32:$K$32)+(DCF!$K$22+DCF!$K$29)*B$14/(1+$A16)^5+Assumptions!$B$6-Assumptions!$B$7)/Assumptions!$B$5 -> 95.356042 | C16: =(NPV($A16,DCF!$G$32:$K$32)+(DCF!$K$22+DCF!$K$29)*C$14/(1+$A16)^5+Assumptions!$B$6-Assumptions!$B$7)/Assumptions!$B$5 -> 100.49589 | D16: =(NPV($A16,DCF!$G$32:$K$32)+(DCF!$K$22+DCF!$K$29)*D$14/(1+$A16)^5+Assumptions!$B$6-Assumptions!$B$7)/Assumptions!$B$5 -> 105.63573 | E16: =(NPV($A16,DCF!$G$32:$K$32)+(DCF!$K$22+DCF!$K$29)*E$14/(1+$A16)^5+Assumptions!$B$6-Assumptions!$B$7)/Assumptions!$B$5 -> 110.77558 | F16: =(NPV($A16,DCF!$G$32:$K$32)+(DCF!$K$22+DCF!$K$29)*F$14/(1+$A16)^5+Assumptions!$B$6-Assumptions!$B$7)/Assumptions!$B$5 -> 115.91543
A17: =Assumptions!$B$14+(0) -> 0.0836385 | B17: =(NPV($A17,DCF!$G$32:$K$32)+(DCF!$K$22+DCF!$K$29)*B$14/(1+$A17)^5+Assumptions!$B$6-Assumptions!$B$7)/Assumptions!$B$5 -> 93.655536 | C17: =(NPV($A17,DCF!$G$32:$K$32)+(DCF!$K$22+DCF!$K$29)*C$14/(1+$A17)^5+Assumptions!$B$6-Assumptions!$B$7)/Assumptions!$B$5 -> 98.677893 | D17: =(NPV($A17,DCF!$G$32:$K$32)+(DCF!$K$22+DCF!$K$29)*D$14/(1+$A17)^5+Assumptions!$B$6-Assumptions!$B$7)/Assumptions!$B$5 -> 103.70025 | E17: =(NPV($A17,DCF!$G$32:$K$32)+(DCF!$K$22+DCF!$K$29)*E$14/(1+$A17)^5+Assumptions!$B$6-Assumptions!$B$7)/Assumptions!$B$5 -> 108.72261 | F17: =(NPV($A17,DCF!$G$32:$K$32)+(DCF!$K$22+DCF!$K$29)*F$14/(1+$A17)^5+Assumptions!$B$6-Assumptions!$B$7)/Assumptions!$B$5 -> 113.74496
A18: =Assumptions!$B$14+(0.005) -> 0.0886385 | B18: =(NPV($A18,DCF!$G$32:$K$32)+(DCF!$K$22+DCF!$K$29)*B$14/(1+$A18)^5+Assumptions!$B$6-Assumptions!$B$7)/Assumptions!$B$5 -> 91.999642 | C18: =(NPV($A18,DCF!$G$32:$K$32)+(DCF!$K$22+DCF!$K$29)*C$14/(1+$A18)^5+Assumptions!$B$6-Assumptions!$B$7)/Assumptions!$B$5 -> 96.907718 | D18: =(NPV($A18,DCF!$G$32:$K$32)+(DCF!$K$22+DCF!$K$29)*D$14/(1+$A18)^5+Assumptions!$B$6-Assumptions!$B$7)/Assumptions!$B$5 -> 101.81579 | E18: =(NPV($A18,DCF!$G$32:$K$32)+(DCF!$K$22+DCF!$K$29)*E$14/(1+$A18)^5+Assumptions!$B$6-Assumptions!$B$7)/Assumptions!$B$5 -> 106.72387 | F18: =(NPV($A18,DCF!$G$32:$K$32)+(DCF!$K$22+DCF!$K$29)*F$14/(1+$A18)^5+Assumptions!$B$6-Assumptions!$B$7)/Assumptions!$B$5 -> 111.63195
A19: =Assumptions!$B$14+(0.01) -> 0.0936385 | B19: =(NPV($A19,DCF!$G$32:$K$32)+(DCF!$K$22+DCF!$K$29)*B$14/(1+$A19)^5+Assumptions!$B$6-Assumptions!$B$7)/Assumptions!$B$5 -> 90.386975 | C19: =(NPV($A19,DCF!$G$32:$K$32)+(DCF!$K$22+DCF!$K$29)*C$14/(1+$A19)^5+Assumptions!$B$6-Assumptions!$B$7)/Assumptions!$B$5 -> 95.183876 | D19: =(NPV($A19,DCF!$G$32:$K$32)+(DCF!$K$22+DCF!$K$29)*D$14/(1+$A19)^5+Assumptions!$B$6-Assumptions!$B$7)/Assumptions!$B$5 -> 99.980777 | E19: =(NPV($A19,DCF!$G$32:$K$32)+(DCF!$K$22+DCF!$K$29)*E$14/(1+$A19)^5+Assumptions!$B$6-Assumptions!$B$7)/Assumptions!$B$5 -> 104.77768 | F19: =(NPV($A19,DCF!$G$32:$K$32)+(DCF!$K$22+DCF!$K$29)*F$14/(1+$A19)^5+Assumptions!$B$6-Assumptions!$B$7)/Assumptions!$B$5 -> 109.57458
